Workbook

Sheet ReservesUSDT
A1: Date | B1: TETHER Total Assets | C1: USDT Issued | D1: Excess Reserves (Equity) | E1: Tether Equity % | F1: CIRCLE Total Assets | G1: USDC Issued | H1: Circle Equity %
A2: 44377 | B2: 62773190075 | C2: 62610829196 | D2: =B2-C2 -> 162360879 | E2: =D2/C2 -> 0.0025931757 | F2: 25158531650 | G2: 25158531650 | H2: =(F2-G2)/G2 -> 0
A3: 44469 | B3: 69156771674 | C3: 68994393701 | D3: =B3-C3 -> 162377973 | E3: =D3/C3 -> 0.0023534952 | F3: 31652676021 | G3: 31652676021 | H3: =(F3-G3)/G3 -> 0
A4: 44561 | B4: 78675642677 | C4: 78480852949 | D4: =B4-C4 -> 194789728 | E4: =D4/C4 -> 0.0024820032 | F4: 42416160651 | G4: 42416160651 | H4: =(F4-G4)/G4 -> 0
A5: 44651 | B5: 82424821101 | C5: 82188190813 | D5: =B5-C5 -> 236630288 | E5: =D5/C5 -> 0.0028791276 | F5: 51388555903 | G5: 51388555903 | H5: =(F5-G5)/G5 -> 0
A6: 44742 | B6: 66409619424 | C6: 66204234509 | D6: =B6-C6 -> 205384915 | E6: =D6/C6 -> 0.0031022927 | F6: 55569660586 | G6: 55569660586 | H6: =(F6-G6)/G6 -> 0
A7: 44834 | B7: 68061618458 | C7: 67805112981 | D7: =B7-C7 -> 256505477 | E7: =D7/C7 -> 0.0037829813 | F7: 47479523936 | G7: 47261819834 | H7: =(F7-G7)/G7 -> 0.0046063419
A8: 44926 | B8: 67044148175 | C8: 66057260169 | D8: =B8-C8 -> 986888006 | E8: =D8/C8 -> 0.014939887 | F8: 44693963701 | G8: 44553543212 | H8: =(F8-G8)/G8 -> 0.0031517244
A9: 45016 | B9: 81833149345 | C9: 79372401626 | D9: =B9-C9 -> 2460747719 | E9: =D9/C9 -> 0.031002561 | F9: 32518607650 | G9: 32518607650 | H9: =(F9-G9)/G9 -> 0
A10: 45107 | B10: 86499251218 | C10: 83178020411 | D10: =B10-C10 -> 3321230807 | E10: =D10/C10 -> 0.039929188 | F10: 27439541303 | G10: 27384351887 | H10: =(F10-G10)/G10 -> 0.0020153632
A11: 45199 | B11: 86384653832 | C11: 83153363663 | D11: =B11-C11 -> 3231290169 | E11: =D11/C11 -> 0.038859404 | F11: 25025027673 | G11: 24973159027 | H11: =(F11-G11)/G11 -> 0.0020769758
A12: 45291 | B12: 97020394556 | C12: 91572956801 | D12: =B12-C12 -> 5447437755 | E12: =D12/C12 -> 0.059487407 | F12: 24693288222 | G12: 24641390742 | H12: =(F12-G12)/G12 -> 0.00210611
A13: 45382 | B13: 110289406409 | C13: 104019279735 | D13: =B13-C13 -> 6270126674 | E13: =D13/C13 -> 0.060278505 | F13: 32425876781 | G13: 32374547608 | H13: =(F13-G13)/G13 -> 0.0015854792
... A20: 46022 | B20: 192877729144 | C20: 186450610920 | D20: =B20-C20 -> 6427118224 | E20: =D20/C20 -> 0.034470889 | F20: 75332981976 | G20: 75266033823 | H20: =(F20-G20)/G20 -> 0.00088948693

Sheet USDT_FinalReserves
A1: Date | B1: Tether Total Assets | C1: USDT Market Cap | D1: Daily Change | F1: New Estimate Reserves
A2: 44834 | B2: 6.8070818e+10 | C2: 6.8018937e+10 | D2: =0 -> 0 | E2: =C2*(1+ReservesUSDT!$E$7) -> 6.8276251e+10 | F2: =E2*(D2+1) -> 6.8276251e+10 | G2: =F2-C2 -> 2.5731437e+08 | H2: =IF(G2>0,1,0) -> 1
A3: 44835 | B3: 6.8056797e+10 | C3: 6.8032464e+10 | D3: =(B3-B2)/B2 -> -0.00020596756 | E3: =C3*(1+ReservesUSDT!$E$7) -> 6.8289829e+10 | F3: =E3*(D3+1) -> 6.8275764e+10 | G3: =F3-C3 -> 2.4330005e+08 | H3: =IF(G3>0,1,0) -> 1
A4: 44836 | B4: 6.8055327e+10 | C4: 6.7985211e+10 | D4: =(B4-B3)/B3 -> -2.1602254e-05 | E4: =C4*(1+ReservesUSDT!$E$7) -> 6.8242398e+10 | F4: =E4*(D4+1) -> 6.8240924e+10 | G4: =F4-C4 -> 2.557126e+08 | H4: =IF(G4>0,1,0) -> 1
A5: 44837 | B5: 6.8360279e+10 | C5: 6.7852871e+10 | D5: =(B5-B4)/B4 -> 0.0044809347 | E5: =C5*(1+ReservesUSDT!$E$7) -> 6.8109557e+10 | F5: =E5*(D5+1) -> 6.8414751e+10 | G5: =F5-C5 -> 5.6188062e+08 | H5: =IF(G5>0,1,0) -> 1
A6: 44838 | B6: 6.7699719e+10 | C6: 6.7955488e+10 | D6: =(B6-B5)/B5 -> -0.0096629154 | E6: =C6*(1+ReservesUSDT!$E$7) -> 6.8212562e+10 | F6: =E6*(D6+1) -> 6.755343e+10 | G6: =F6-C6 -> -4.0205787e+08 | H6: =IF(G6>0,1,0) -> 0
A7: 44839 | B7: 6.7697961e+10 | C7: 6.8146473e+10 | D7: =(B7-B6)/B6 -> -2.5963498e-05 | E7: =C7*(1+ReservesUSDT!$E$7) -> 6.840427e+10 | F7: =E7*(D7+1) -> 6.8402494e+10 | G7: =F7-C7 -> 2.5602082e+08 | H7: =IF(G7>0,1,0) -> 1
A8: 44840 | B8: 6.7664362e+10 | C8: 6.8249512e+10 | D8: =(B8-B7)/B7 -> -0.0004963142 | E8: =C8*(1+ReservesUSDT!$E$7) -> 6.8507699e+10 | F8: =E8*(D8+1) -> 6.8473697e+10 | G8: =F8-C8 -> 2.2418529e+08 | H8: =IF(G8>0,1,0) -> 1
A9: 44841 | B9: 6.7689547e+10 | C9: 6.8240187e+10 | D9: =(B9-B8)/B8 -> 0.00037220743 | E9: =C9*(1+ReservesUSDT!$E$7) -> 6.8498338e+10 | F9: =E9*(D9+1) -> 6.8523834e+10 | G9: =F9-C9 -> 2.8364694e+08 | H9: =IF(G9>0,1,0) -> 1
A10: 44842 | B10: 6.7681807e+10 | C10: 6.8360023e+10 | D10: =(B10-B9)/B9 -> -0.00011433949 | E10: =C10*(1+ReservesUSDT!$E$7) -> 6.8618628e+10 | F10: =E10*(D10+1) -> 6.8610782e+10 | G10: =F10-C10 -> 2.5075887e+08 | H10: =IF(G10>0,1,0) -> 1
A11: 44843 | B11: 6.7684175e+10 | C11: 6.838466e+10 | D11: =(B11-B10)/B10 -> 3.4985781e-05 | E11: =C11*(1+ReservesUSDT!$E$7) -> 6.8643358e+10 | F11: =E11*(D11+1) -> 6.8645759e+10 | G11: =F11-C11 -> 2.6109943e+08 | H11: =IF(G11>0,1,0) -> 1
A12: 44844 | B12: 6.7616413e+10 | C12: 6.8308302e+10 | D12: =(B12-B11)/B11 -> -0.0010011544 | E12: =C12*(1+ReservesUSDT!$E$7) -> 6.8566711e+10 | F12: =E12*(D12+1) -> 6.8498065e+10 | G12: =F12-C12 -> 1.8976317e+08 | H12: =IF(G12>0,1,0) -> 1
A13: 44845 | B13: 6.7171357e+10 | C13: 6.846553e+10 | D13: =(B13-B12)/B12 -> -0.0065820745 | E13: =C13*(1+ReservesUSDT!$E$7) -> 6.8724534e+10 | F13: =E13*(D13+1) -> 6.8272184e+10 | G13: =F13-C13 -> -1.9334618e+08 | H13: =IF(G13>0,1,0) -> 0
A14: 44846 | B14: 6.6329591e+10 | C14: 6.8428562e+10 | D14: =(B14-B13)/B13 -> -0.012531614 | E14: =C14*(1+ReservesUSDT!$E$7) -> 6.8687426e+10 | F14: =E14*(D14+1) -> 6.7826661e+10 | G14: =F14-C14 -> -6.019003e+08 | H14: =IF(G14>0,1,0) -> 0
... A93: 44925 | B93: 6.2761996e+10 | C93: 6.6255816e+10 | D93: =(B93-B92)/B92 -> 0.0012852454 | E93: =C93*(1+ReservesUSDT!$E$7) -> 6.650646e+10 | F93: =E93*(D93+1) -> 6.6591937e+10 | G93: =F93-C93 -> 3.3612164e+08 | H93: =IF(G93>0,1,0) -> 1
A94: 44926 | B94: 6.7035861e+10 | C94: 6.6279044e+10 | D94: =0 -> 0 | E94: =C94*(1+ReservesUSDT!$E$8) -> 6.7269245e+10 | F94: =E94*(D94+1) -> 6.7269245e+10 | G94: =F94-C94 -> 9.9020142e+08 | H94: =IF(G94>0,1,0) -> 1
A95: 44927 | B95: 6.704198e+10 | C95: 6.6226452e+10 | D95: =(B95-B94)/B94 -> 9.1282944e-05 | E95: =C95*(1+ReservesUSDT!$E$8) -> 6.7215867e+10 | F95: =E95*(D95+1) -> 6.7222003e+10 | G95: =F95-C95 -> 9.9555137e+08 | H95: =IF(G95>0,1,0) -> 1
A96: 44928 | B96: 6.7056356e+10 | C96: 6.6301858e+10 | D96: =(B96-B95)/B95 -> 0.00021442955 | E96: =C96*(1+ReservesUSDT!$E$8) -> 6.7292401e+10 | F96: =E96*(D96+1) -> 6.730683e+10 | G96: =F96-C96 -> 1.0049718e+09 | H96: =IF(G96>0,1,0) -> 1
A97: 44929 | B97: 6.7117597e+10 | C97: 6.6223252e+10 | D97: =(B97-B96)/B96 -> 0.00091327611 | E97: =C97*(1+ReservesUSDT!$E$8) -> 6.721262e+10 | F97: =E97*(D97+1) -> 6.7274003e+10 | G97: =F97-C97 -> 1.0507516e+09 | H97: =IF(G97>0,1,0) -> 1
A98: 44930 | B98: 6.6235291e+10 | C98: 6.6274059e+10 | D98: =(B98-B97)/B97 -> -0.013145663 | E98: =C98*(1+ReservesUSDT!$E$8) -> 6.7264186e+10 | F98: =E98*(D98+1) -> 6.6379954e+10 | G98: =F98-C98 -> 1.0589465e+08 | H98: =IF(G98>0,1,0) -> 1
A99: 44931 | B99: 6.5538973e+10 | C99: 6.6245546e+10 | D99: =(B99-B98)/B98 -> -0.010512795 | E99: =C99*(1+ReservesUSDT!$E$8) -> 6.7235247e+10 | F99: =E99*(D99+1) -> 6.6528416e+10 | G99: =F99-C99 -> 2.828706e+08 | H99: =IF(G99>0,1,0) -> 1
A100: 44932 | B100: 6.5648024e+10 | C100: 6.6278649e+10 | D100: =(B100-B99)/B99 -> 0.0016639054 | E100: =C100*(1+ReservesUSDT!$E$8) -> 6.7268844e+10 | F100: =E100*(D100+1) -> 6.7380773e+10 | G100: =F100-C100 -> 1.1021245e+09 | H100: =IF(G100>0,1,0) -> 1
A101: 44933 | B101: 6.564906e+10 | C101: 6.6263334e+10 | D101: =(B101-B100)/B100 -> 1.5784001e-05 | E101: =C101*(1+ReservesUSDT!$E$8) -> 6.7253301e+10 | F101: =E101*(D101+1) -> 6.7254363e+10 | G101: =F101-C101 -> 9.9102826e+08 | H101: =IF(G101>0,1,0) -> 1
A102: 44934 | B102: 6.5650816e+10 | C102: 6.6272452e+10 | D102: =(B102-B101)/B101 -> 2.6739358e-05 | E102: =C102*(1+ReservesUSDT!$E$8) -> 6.7262555e+10 | F102: =E102*(D102+1) -> 6.7264353e+10 | G102: =F102-C102 -> 9.919015e+08 | H102: =IF(G102>0,1,0) -> 1
A103: 44935 | B103: 6.5665575e+10 | C103: 6.629536e+10 | D103: =(B103-B102)/B102 -> 0.00022482553 | E103: =C103*(1+ReservesUSDT!$E$8) -> 6.7285805e+10 | F103: =E103*(D103+1) -> 6.7300933e+10 | G103: =F103-C103 -> 1.0055728e+09 | H103: =IF(G103>0,1,0) -> 1
A104: 44936 | B104: 6.5681509e+10 | C104: 6.6315047e+10 | D104: =(B104-B103)/B103 -> 0.00024264164 | E104: =C104*(1+ReservesUSDT!$E$8) -> 6.7305786e+10 | F104: =E104*(D104+1) -> 6.7322118e+10 | G104: =F104-C104 -> 1.0070705e+09 | H104: =IF(G104>0,1,0) -> 1
A105: 44937 | B105: 6.5331725e+10 | C105: 6.6307829e+10 | D105: =(B105-B104)/B104 -> -0.0053254523 | E105: =C105*(1+ReservesUSDT!$E$8) -> 6.729846e+10 | F105: =E105*(D105+1) -> 6.6940066e+10 | G105: =F105-C105 -> 6.3223673e+08 | H105: =IF(G105>0,1,0) -> 1
A106: 44938 | B106: 6.5983066e+10 | C106: 6.5470424e+10 | D106: =(B106-B105)/B105 -> 0.0099697574 | E106: =C106*(1+ReservesUSDT!$E$8) -> 6.6448545e+10 | F106: =E106*(D106+1) -> 6.7111021e+10 | G106: =F106-C106 -> 1.6405966e+09 | H106: =IF(G106>0,1,0) -> 1
... A183: 45015 | B183: 6.5401381e+10 | C183: 7.963637e+10 | D183: =(B183-B182)/B182 -> -0.0069694713 | E183: =C183*(1+ReservesUSDT!$E$8) -> 8.0826129e+10 | F183: =E183*(D183+1) -> 8.0262813e+10 | G183: =F183-C183 -> 6.26443e+08 | H183: =IF(G183>0,1,0) -> 1
A184: 45016 | B184: 8.183232e+10 | C184: 7.9708195e+10 | D184: 0 | E184: =C184*(1+ReservesUSDT!$E$9) -> 8.2179353e+10 | F184: =E184*(D184+1) -> 8.2179353e+10 | G184: =F184-C184 -> 2.4711582e+09 | H184: =IF(G184>0,1,0) -> 1
A185: 45017 | B185: 8.1835936e+10 | C185: 7.9808588e+10 | D185: =(B185-B184)/B184 -> 4.4177259e-05 | E185: =C185*(1+ReservesUSDT!$E$9) -> 8.2282859e+10 | F185: =E185*(D185+1) -> 8.2286494e+10 | G185: =F185-C185 -> 2.4779056e+09 | H185: =IF(G185>0,1,0) -> 1
A186: 45018 | B186: 8.181551e+10 | C186: 7.9772057e+10 | D186: =(B186-B185)/B185 -> -0.00024958694 | E186: =C186*(1+ReservesUSDT!$E$9) -> 8.2245195e+10 | F186: =E186*(D186+1) -> 8.2224667e+10 | G186: =F186-C186 -> 2.4526107e+09 | H186: =IF(G186>0,1,0) -> 1
A187: 45019 | B187: 8.1726132e+10 | C187: 7.9792661e+10 | D187: =(B187-B186)/B186 -> -0.0010924404 | E187: =C187*(1+ReservesUSDT!$E$9) -> 8.2266437e+10 | F187: =E187*(D187+1) -> 8.2176566e+10 | G187: =F187-C187 -> 2.3839056e+09 | H187: =IF(G187>0,1,0) -> 1
A188: 45020 | B188: 8.1244193e+10 | C188: 7.9874799e+10 | D188: =(B188-B187)/B187 -> -0.0058969921 | E188: =C188*(1+ReservesUSDT!$E$9) -> 8.2351123e+10 | F188: =E188*(D188+1) -> 8.1865499e+10 | G188: =F188-C188 -> 1.9906994e+09 | H188: =IF(G188>0,1,0) -> 1
A189: 45021 | B189: 8.0917394e+10 | C189: 8.0081067e+10 | D189: =(B189-B188)/B188 -> -0.0040224374 | E189: =C189*(1+ReservesUSDT!$E$9) -> 8.2563786e+10 | F189: =E189*(D189+1) -> 8.2231678e+10 | G189: =F189-C189 -> 2.1506105e+09 | H189: =IF(G189>0,1,0) -> 1
A190: 45022 | B190: 8.0721388e+10 | C190: 8.0140267e+10 | D190: =(B190-B189)/B189 -> -0.0024222982 | E190: =C190*(1+ReservesUSDT!$E$9) -> 8.262482e+10 | F190: =E190*(D190+1) -> 8.2424678e+10 | G190: =F190-C190 -> 2.2844116e+09 | H190: =IF(G190>0,1,0) -> 1
A191: 45023 | B191: 8.0456132e+10 | C191: 8.0188675e+10 | D191: =(B191-B190)/B190 -> -0.0032860592 | E191: =C191*(1+ReservesUSDT!$E$9) -> 8.267473e+10 | F191: =E191*(D191+1) -> 8.2403056e+10 | G191: =F191-C191 -> 2.2143802e+09 | H191: =IF(G191>0,1,0) -> 1
A192: 45024 | B192: 8.0458353e+10 | C192: 8.0268298e+10 | D192: =(B192-B191)/B191 -> 2.7601547e-05 | E192: =C192*(1+ReservesUSDT!$E$9) -> 8.2756821e+10 | F192: =E192*(D192+1) -> 8.2759105e+10 | G192: =F192-C192 -> 2.490807e+09 | H192: =IF(G192>0,1,0) -> 1
A193: 45025 | B193: 8.0469126e+10 | C193: 8.0306858e+10 | D193: =(B193-B192)/B192 -> 0.0001338894 | E193: =C193*(1+ReservesUSDT!$E$9) -> 8.2796576e+10 | F193: =E193*(D193+1) -> 8.2807662e+10 | G193: =F193-C193 -> 2.5008038e+09 | H193: =IF(G193>0,1,0) -> 1
A194: 45026 | B194: 7.8738922e+10 | C194: 8.0310814e+10 | D194: =(B194-B193)/B193 -> -0.021501465 | E194: =C194*(1+ReservesUSDT!$E$9) -> 8.2800655e+10 | F194: =E194*(D194+1) -> 8.102032e+10 | G194: =F194-C194 -> 7.0950552e+08 | H194: =IF(G194>0,1,0) -> 1
...

Sheet USDC_Final Reserve
A1: Date | B1: Circle Total Assets | C1: market_cap | D1: Daily Change | F1: New Estimate Reserves | G1: Change
A2: 44834 | B2: 47479523938 | C2: 47479523938 | D2: =0 -> 0 | E2: =C2*(1+ReservesUSDT!$H$7) -> 4.7698231e+10 | F2: =E2*(D2+1) -> 4.7698231e+10 | I2: =F2-C2 -> 2.1870692e+08 | J2: =IF(I2>0,1,0) -> 1
A3: 44835 | B3: 47479523938 | C3: 4.7317567e+10 | D3: =(B3-B2)/B2 -> 0 | E3: =C3*(1+ReservesUSDT!$H$7) -> 4.7535527e+10 | F3: =E3*(D3+1) -> 4.7535527e+10 | G3: =(F3-F2)/F2 -> -0.0034110998 | I3: =F3-C3 -> 2.1796089e+08 | J3: =IF(I3>0,1,0) -> 1
A4: 44836 | B4: 47479523938 | C4: 4.7217028e+10 | D4: =(B4-B3)/B3 -> 0 | E4: =C4*(1+ReservesUSDT!$H$7) -> 4.7434526e+10 | F4: =E4*(D4+1) -> 4.7434526e+10 | G4: =(F4-F3)/F3 -> -0.0021247532 | I4: =F4-C4 -> 2.1749778e+08 | J4: =IF(I4>0,1,0) -> 1
A5: 44837 | B5: 4.7862191e+10 | C5: 4.7429206e+10 | D5: =(B5-B4)/B4 -> 0.0080596145 | E5: =C5*(1+ReservesUSDT!$H$7) -> 4.7647681e+10 | F5: =E5*(D5+1) -> 4.8031703e+10 | G5: =(F5-F4)/F4 -> 0.01258949 | I5: =F5-C5 -> 6.0249708e+08 | J5: =IF(I5>0,1,0) -> 1
A6: 44838 | B6: 4.6383854e+10 | C6: 4.7127777e+10 | D6: =(B6-B5)/B5 -> -0.030887365 | E6: =C6*(1+ReservesUSDT!$H$7) -> 4.7344864e+10 | F6: =E6*(D6+1) -> 4.5882506e+10 | G6: =(F6-F5)/F5 -> -0.044745377 | I6: =F6-C6 -> -1.2452715e+09 | J6: =IF(I6>0,1,0) -> 0
A7: 44839 | B7: 4.6476781e+10 | C7: 4.6767463e+10 | D7: =(B7-B6)/B6 -> 0.0020034448 | E7: =C7*(1+ReservesUSDT!$H$7) -> 4.698289e+10 | F7: =E7*(D7+1) -> 4.7077017e+10 | G7: =(F7-F6)/F6 -> 0.026034136 | I7: =F7-C7 -> 3.0955455e+08 | J7: =IF(I7>0,1,0) -> 1
A8: 44840 | B8: 4.6430201e+10 | C8: 4.6412465e+10 | D8: =(B8-B7)/B7 -> -0.0010022188 | E8: =C8*(1+ReservesUSDT!$H$7) -> 4.6626257e+10 | F8: =E8*(D8+1) -> 4.6579527e+10 | G8: =(F8-F7)/F7 -> -0.01056758 | I8: =F8-C8 -> 1.6706197e+08 | J8: =IF(I8>0,1,0) -> 1
A9: 44841 | B9: 4.6634897e+10 | C9: 4.6188993e+10 | D9: =(B9-B8)/B8 -> 0.004408669 | E9: =C9*(1+ReservesUSDT!$H$7) -> 4.6401756e+10 | F9: =E9*(D9+1) -> 4.6606326e+10 | G9: =(F9-F8)/F8 -> 0.00057532732 | I9: =F9-C9 -> 4.1733228e+08 | J9: =IF(I9>0,1,0) -> 1
A10: 44842 | B10: 4.6634897e+10 | C10: 4.6210938e+10 | D10: =(B10-B9)/B9 -> 0 | E10: =C10*(1+ReservesUSDT!$H$7) -> 4.6423801e+10 | F10: =E10*(D10+1) -> 4.6423801e+10 | G10: =(F10-F9)/F9 -> -0.0039163074 | I10: =F10-C10 -> 2.1286338e+08 | J10: =IF(I10>0,1,0) -> 1
A11: 44843 | B11: 4.6634897e+10 | C11: 4.6054962e+10 | D11: =(B11-B10)/B10 -> 0 | E11: =C11*(1+ReservesUSDT!$H$7) -> 4.6267106e+10 | F11: =E11*(D11+1) -> 4.6267106e+10 | G11: =(F11-F10)/F10 -> -0.0033753078 | I11: =F11-C11 -> 2.121449e+08 | J11: =IF(I11>0,1,0) -> 1
A12: 44844 | B12: 4.6634897e+10 | C12: 4.5974636e+10 | D12: =(B12-B11)/B11 -> 0 | E12: =C12*(1+ReservesUSDT!$H$7) -> 4.6186411e+10 | F12: =E12*(D12+1) -> 4.6186411e+10 | G12: =(F12-F11)/F11 -> -0.0017441119 | I12: =F12-C12 -> 2.117749e+08 | J12: =IF(I12>0,1,0) -> 1
A13: 44845 | B13: 4.5849034e+10 | C13: 4.5967669e+10 | D13: =(B13-B12)/B12 -> -0.01685139 | E13: =C13*(1+ReservesUSDT!$H$7) -> 4.6179412e+10 | F13: =E13*(D13+1) -> 4.5401225e+10 | G13: =(F13-F12)/F12 -> -0.017000383 | I13: =F13-C13 -> -5.6644446e+08 | J13: =IF(I13>0,1,0) -> 0
A14: 44846 | B14: 4.4237042e+10 | C14: 4.5948598e+10 | D14: =(B14-B13)/B13 -> -0.035158685 | E14: =C14*(1+ReservesUSDT!$H$7) -> 4.6160253e+10 | F14: =E14*(D14+1) -> 4.4537319e+10 | G14: =(F14-F13)/F13 -> -0.019028238 | I14: =F14-C14 -> -1.4112788e+09 | J14: =IF(I14>0,1,0) -> 0
... A93: 44925 | B93: 3.8094662e+10 | C93: 4.440697e+10 | D93: =(B93-B92)/B92 -> 0.0030297045 | E93: =C93*(1+ReservesUSDT!$H$7) -> 4.4611524e+10 | F93: =E93*(D93+1) -> 4.4746683e+10 | G93: =(F93-F92)/F92 -> -0.0067558396 | I93: =F93-C93 -> 3.3971342e+08 | J93: =IF(I93>0,1,0) -> 1
A94: 44926 | B94: 44693963701 | C94: 4.4523298e+10 | D94: 0 | E94: =C94*(1+ReservesUSDT!$H$8) -> 4.4663623e+10 | F94: =E94*(D94+1) -> 4.4663623e+10 | G94: =(F94-F93)/F93 -> -0.0018562346 | I94: =F94-C94 -> 1.4032516e+08 | J94: =IF(I94>0,1,0) -> 1
A95: 44927 | B95: 44693963701 | C95: 4.4528657e+10 | D95: =(B95-B94)/B94 -> 0 | E95: =C95*(1+ReservesUSDT!$H$8) -> 4.4668999e+10 | F95: =E95*(D95+1) -> 4.4668999e+10 | G95: =(F95-F94)/F94 -> 0.00012037388 | I95: =F95-C95 -> 1.4034206e+08 | J95: =IF(I95>0,1,0) -> 1
A96: 44928 | B96: 44693963701 | C96: 4.4601804e+10 | D96: =(B96-B95)/B95 -> 0 | E96: =C96*(1+ReservesUSDT!$H$8) -> 4.4742376e+10 | F96: =E96*(D96+1) -> 4.4742376e+10 | G96: =(F96-F95)/F95 -> 0.0016426871 | I96: =F96-C96 -> 1.4057259e+08 | J96: =IF(I96>0,1,0) -> 1
A97: 44929 | B97: 4.4745122e+10 | C97: 4.4694019e+10 | D97: =(B97-B96)/B96 -> 0.0011446353 | E97: =C97*(1+ReservesUSDT!$H$8) -> 4.4834882e+10 | F97: =E97*(D97+1) -> 4.4886202e+10 | G97: =(F97-F96)/F96 -> 0.0032145263 | I97: =F97-C97 -> 1.9218282e+08 | J97: =IF(I97>0,1,0) -> 1
A98: 44930 | B98: 4.3541099e+10 | C98: 4.4202124e+10 | D98: =(B98-B97)/B97 -> -0.026908477 | E98: =C98*(1+ReservesUSDT!$H$8) -> 4.4341437e+10 | F98: =E98*(D98+1) -> 4.3148276e+10 | G98: =(F98-F97)/F97 -> -0.03871848 | I98: =F98-C98 -> -1.0538476e+09 | J98: =IF(I98>0,1,0) -> 0
A99: 44931 | B99: 4.2700806e+10 | C99: 4.4135426e+10 | D99: =(B99-B98)/B98 -> -0.019298843 | E99: =C99*(1+ReservesUSDT!$H$8) -> 4.4274529e+10 | F99: =E99*(D99+1) -> 4.3420081e+10 | G99: =(F99-F98)/F98 -> 0.0062993227 | I99: =F99-C99 -> -7.1534447e+08 | J99: =IF(I99>0,1,0) -> 0
A100: 44932 | B100: 4.2748975e+10 | C100: 4.376343e+10 | D100: =(B100-B99)/B99 -> 0.0011280478 | E100: =C100*(1+ReservesUSDT!$H$8) -> 4.390136e+10 | F100: =E100*(D100+1) -> 4.3950883e+10 | G100: =(F100-F99)/F99 -> 0.012224791 | I100: =F100-C100 -> 1.874531e+08 | J100: =IF(I100>0,1,0) -> 1
A101: 44933 | B101: 4.2748975e+10 | C101: 4.3712867e+10 | D101: =(B101-B100)/B100 -> 0 | E101: =C101*(1+ReservesUSDT!$H$8) -> 4.3850638e+10 | F101: =E101*(D101+1) -> 4.3850638e+10 | G101: =(F101-F100)/F100 -> -0.0022808469 | I101: =F101-C101 -> 1.3777091e+08 | J101: =IF(I101>0,1,0) -> 1
A102: 44934 | B102: 4.2748975e+10 | C102: 4.3815414e+10 | D102: =(B102-B101)/B101 -> 0 | E102: =C102*(1+ReservesUSDT!$H$8) -> 4.3953508e+10 | F102: =E102*(D102+1) -> 4.3953508e+10 | G102: =(F102-F101)/F101 -> 0.0023459362 | I102: =F102-C102 -> 1.3809411e+08 | J102: =IF(I102>0,1,0) -> 1
A103: 44935 | B103: 4.2716814e+10 | C103: 4.3973957e+10 | D103: =(B103-B102)/B102 -> -0.00075231128 | E103: =C103*(1+ReservesUSDT!$H$8) -> 4.4112551e+10 | F103: =E103*(D103+1) -> 4.4079364e+10 | G103: =(F103-F102)/F102 -> 0.0028633911 | I103: =F103-C103 -> 1.0540742e+08 | J103: =IF(I103>0,1,0) -> 1
A104: 44936 | B104: 4.2692718e+10 | C104: 4.4012648e+10 | D104: =(B104-B103)/B103 -> -0.0005640936 | E104: =C104*(1+ReservesUSDT!$H$8) -> 4.4151364e+10 | F104: =E104*(D104+1) -> 4.4126458e+10 | G104: =(F104-F103)/F103 -> 0.0010683916 | I104: =F104-C104 -> 1.1381024e+08 | J104: =IF(I104>0,1,0) -> 1
A105: 44937 | B105: 4.2235232e+10 | C105: 4.3685112e+10 | D105: =(B105-B104)/B104 -> -0.010715785 | E105: =C105*(1+ReservesUSDT!$H$8) -> 4.3822796e+10 | F105: =E105*(D105+1) -> 4.33532e+10 | G105: =(F105-F104)/F104 -> -0.017523691 | I105: =F105-C105 -> -3.3191221e+08 | J105: =IF(I105>0,1,0) -> 0
A106: 44938 | B106: 4.2860256e+10 | C106: 4.3929682e+10 | D106: =(B106-B105)/B105 -> 0.014798644 | E106: =C106*(1+ReservesUSDT!$H$8) -> 4.4068137e+10 | F106: =E106*(D106+1) -> 4.4720285e+10 | G106: =(F106-F105)/F105 -> 0.031533665 | I106: =F106-C106 -> 7.9060292e+08 | J106: =IF(I106>0,1,0) -> 1
... A183: 45015 | B183: 4.0818312e+10 | C183: 3.3299623e+10 | D183: =(B183-B182)/B182 -> -0.014141018 | E183: =C183*(1+ReservesUSDT!$H$8) -> 3.3404574e+10 | F183: =E183*(D183+1) -> 3.2932199e+10 | G183: =(F183-F182)/F182 -> -0.0058221247 | I183: =F183-C183 -> -3.6742345e+08 | J183: =IF(I183>0,1,0) -> 0
A184: 45016 | B184: 32571701308 | C184: 3.2875147e+10 | D184: 0 | E184: =C184*(1+ReservesUSDT!$H$9) -> 3.2875147e+10 | F184: =E184*(D184+1) -> 3.2875147e+10 | G184: =(F184-F183)/F183 -> -0.0017324113 | I184: =F184-C184 -> 0 | J184: =IF(I184>0,1,0) -> 0
A185: 45017 | B185: 32571701308 | C185: 3.2545003e+10 | D185: =(B185-B184)/B184 -> 0 | E185: =C185*(1+ReservesUSDT!$H$9) -> 3.2545003e+10 | F185: =E185*(D185+1) -> 3.2545003e+10 | G185: =(F185-F184)/F184 -> -0.010042368 | I185: =F185-C185 -> 0 | J185: =IF(I185>0,1,0) -> 0
A186: 45018 | B186: 32571701308 | C186: 3.2545587e+10 | D186: =(B186-B185)/B185 -> 0 | E186: =C186*(1+ReservesUSDT!$H$9) -> 3.2545587e+10 | F186: =E186*(D186+1) -> 3.2545587e+10 | G186: =(F186-F185)/F185 -> 1.7931375e-05 | I186: =F186-C186 -> 0 | J186: =IF(I186>0,1,0) -> 0
A187: 45019 | B187: 3.2521808e+10 | C187: 3.2564611e+10 | D187: =(B187-B186)/B186 -> -0.0015318032 | E187: =C187*(1+ReservesUSDT!$H$9) -> 3.2564611e+10 | F187: =E187*(D187+1) -> 3.2514729e+10 | G187: =(F187-F186)/F186 -> -0.00094814246 | I187: =F187-C187 -> -49882576 | J187: =IF(I187>0,1,0) -> 0
A188: 45020 | B188: 3.2208741e+10 | C188: 3.2678368e+10 | D188: =(B188-B187)/B187 -> -0.0096263731 | E188: =C188*(1+ReservesUSDT!$H$9) -> 3.2678368e+10 | F188: =E188*(D188+1) -> 3.2363794e+10 | G188: =(F188-F187)/F187 -> -0.0046420421 | I188: =F188-C188 -> -3.1457416e+08 | J188: =IF(I188>0,1,0) -> 0
A189: 45021 | B189: 3.2032818e+10 | C189: 3.2706456e+10 | D189: =(B189-B188)/B188 -> -0.0054619441 | E189: =C189*(1+ReservesUSDT!$H$9) -> 3.2706456e+10 | F189: =E189*(D189+1) -> 3.2527815e+10 | G189: =(F189-F188)/F188 -> 0.0050680351 | I189: =F189-C189 -> -1.7864083e+08 | J189: =IF(I189>0,1,0) -> 0
A190: 45022 | B190: 3.1941911e+10 | C190: 3.2640958e+10 | D190: =(B190-B189)/B189 -> -0.0028379604 | E190: =C190*(1+ReservesUSDT!$H$9) -> 3.2640958e+10 | F190: =E190*(D190+1) -> 3.2548324e+10 | G190: =(F190-F189)/F189 -> 0.00063051908 | I190: =F190-C190 -> -92633745 | J190: =IF(I190>0,1,0) -> 0
A191: 45023 | B191: 3.1809477e+10 | C191: 3.2758617e+10 | D191: =(B191-B190)/B190 -> -0.0041460743 | E191: =C191*(1+ReservesUSDT!$H$9) -> 3.2758617e+10 | F191: =E191*(D191+1) -> 3.2622797e+10 | G191: =(F191-F190)/F190 -> 0.0022880645 | I191: =F191-C191 -> -1.3581966e+08 | J191: =IF(I191>0,1,0) -> 0
A192: 45024 | B192: 3.1809477e+10 | C192: 3.2617421e+10 | D192: =(B192-B191)/B191 -> 0 | E192: =C192*(1+ReservesUSDT!$H$9) -> 3.2617421e+10 | F192: =E192*(D192+1) -> 3.2617421e+10 | G192: =(F192-F191)/F191 -> -0.00016478602 | I192: =F192-C192 -> 0 | J192: =IF(I192>0,1,0) -> 0
A193: 45025 | B193: 3.1809477e+10 | C193: 3.2622414e+10 | D193: =(B193-B192)/B192 -> 0 | E193: =C193*(1+ReservesUSDT!$H$9) -> 3.2622414e+10 | F193: =E193*(D193+1) -> 3.2622414e+10 | G193: =(F193-F192)/F192 -> 0.00015308069 | I193: =F193-C193 -> 0 | J193: =IF(I193>0,1,0) -> 0
A194: 45026 | B194: 3.0872972e+10 | C194: 3.2618005e+10 | D194: =(B194-B193)/B193 -> -0.029441084 | E194: =C194*(1+ReservesUSDT!$H$9) -> 3.2618005e+10 | F194: =E194*(D194+1) -> 3.1657696e+10 | G194: =(F194-F193)/F193 -> -0.029572256 | I194: =F194-C194 -> -9.6030943e+08 | J194: =IF(I194>0,1,0) -> 0
...

Sheet ReservesCompositionDetailed
A1: Date | B1: CDs/CPs | C1: Cash&BanksDepo | D1: O/N Repo | E1: Reverse Repo | F1: Money Mkts | G1: Tbills | H1: Non US Tbills | I1: SecuredLoans | J1: Corporate Bonds | K1: Metals and CB | L1: BTC | M1: Other Inv (Digital tokens) | N1: Cash & Equivalents | O1: Other Assets | P1: Avg Duration CPs/CDs | Q1: Avg RatingCPs/CDs | R1: Comments | S1: Tbills Duration | T1: Non US Tbills Duration | U1: Corporate bond maturity | V1: Reverse Repo Duration | W1: BTC Price for valuation (YF price Adj close before 2024) | X1: #BTC Held | Y1: % BTC/Other Inv | Z1: O/N OIS | AA1: 3m OIS | AB1: Gold Price | AC1: FX (maybe consider them hedged and use 3m rate + Spread | AD1: UST 3m | AE1: UST curve | AF1: IG Spread
A2: 44377 | B2: 30807654349 | C2: 6282756692 | D2: 1000662458 | F2: 0 | G2: 15279528705 | H2: 0 | I2: 2517140390 | K2: 4830821277 | M2: 2054626204 | O2: =SUM(I2:M2) -> 9402587871 | P2: 150 days | Q2: A-2 | R2: =SUM(B2:M2)-ReservesUSDT!B2 -> 0
A3: 44469 | B3: 30595197667 | C3: 7237204694 | D3: 0 | F3: 999989000 | G3: 19434280489 | H3: 0 | I3: 3452029190 | K3: 3607629331 | M3: 3830441303 | N3: =SUM(B3:H3)/SUM(B3:M3) -> 0.84253025 | O3: =SUM(I3:M3) -> 10890099824 | P3: 141 days | Q3: A-2 | R3: =SUM(B3:M3)-ReservesUSDT!B3 -> 0
A4: 44561 | B4: 24165815363 | C4: 4187004507 | D4: 0 | F4: 3000083600 | G4: 34527886113 | H4: 0 | I4: 4142957365 | K4: 3628506483 | M4: 5023389246 | N4: =SUM(B4:H4)/SUM(B4:M4) -> 0.83737212 | O4: =SUM(I4:M4) -> 12794853094 | P4: 80 days | Q4: A-2 | R4: =SUM(B4:M4)-ReservesUSDT!B4 -> 0
A5: 44651 | B5: 20096579998 | C5: 4100485805 | D5: 105331269 | F5: 6798150552 | G5: 39199221428 | H5: 286155289 | I5: 3149732368 | K5: 3729529946 | M5: 4959634446 | N5: =SUM(B5:H5)/SUM(B5:M5) -> 0.85636733 | O5: =SUM(I5:M5) -> 11838896760 | P5: 44 days | Q5: A-1 | R5: =SUM(B5:M5)-ReservesUSDT!B5 -> 0
A6: 44742 | B6: 8402426505 | C6: 5418232067 | D6: 2992015954 | F6: 6810253431 | G6: 28856434491 | H6: 397150678 | I6: 4494373260 | K6: 3486896735 | M6: 5551836303 | N6: =SUM(B6:H6)/SUM(B6:M6) -> 0.79621768 | O6: =SUM(I6:M6) -> 13533106298 | P6: 27 days | Q6: A-1 | R6: =SUM(B6:M6)-ReservesUSDT!B6 -> 0
A7: 44834 | B7: 49981855 | C7: 6077722223 | E7: 3023814393 | F7: 7101935591 | G7: 39678465980 | H7: 182114357 | I7: 6135946415 | K7: 3194369894 | L7: 0 | M7: 2617267750 | N7: =SUM(B7:H7)/SUM(B7:M7) -> 0.8244593 | O7: =SUM(I7:M7) -> 11947584059 | P7: 15 days | Q7: A-1+ | R7: 10bps redepemption | S7: 45 | T7: 90 | U7: - | V7: - | W7: 19312 | X7: =L7/W7 -> 0
A8: 44926 | B8: - | C8: 5318311794 | E8: 3046093954 | F8: 7372926391 | G8: 39230259046 | H8: 93849833 | I8: 5852823328 | K8: 3444097599 | L8: 0 | M8: 2685786230 | N8: =SUM(B8:H8)/SUM(B8:M8) -> 0.82127139 | O8: =SUM(I8:M8) -> 11982707157 | P8: - | Q8: - | R8: 10bps redepemption | S8: 60 | T8: 90 | U8: - | V8: - | W8: 16625 | X8: =L8/W8 -> 0
A9: 45016 | B9: - | C9: 481350555 | D9: =7500000000 -> 7500000000 | E9: 786850807 | F9: 7453204896 | G9: 53044762609 | H9: 47680940 | I9: 5349078821 | J9: 140669244 | K9: =3391091658 -> 3391091658 | L9: 1500064140 | M9: =2138395675 -> 2138395675 | N9: =SUM(B9:H9)/SUM(B9:M9) -> 0.84701433 | O9: =SUM(I9:M9) -> 12519299538 | R9: 10bps redepemption | S9: 90 | T9: 180 | U9: 210 | V9: 90 | W9: 28411 | X9: =L9/W9 -> 52798.71 | Y9: =L9/(L9+M9) -> 0.41227998
A10: 45107 | B10: - | C10: 90811797 | D10: =8893000000 -> 8893000000 | E10: 577232281 | F10: 8133865426 | G10: 55809730658 | H10: 62937172 | I10: 5504292639 | J10: 115496758 | K10: =3270216824 -> 3270216824 | L10: 2365438303 | M10: =1676229360 -> 1676229360 | N10: =SUM(B10:H10)/SUM(B10:M10) -> 0.85049959 | O10: =SUM(I10:M10) -> 12931673884 | P10: - | Q10: - | R10: 10bps redepemption | S10: 90 | T10: 450 | U10: 180 | V10: 90 | W10: 30590 | X10: =L10/W10 -> 77327.176 | Y10: =L10/(L10+M10) -> 0.58526294
A11: 45199 | B11: - | C11: 292641978 | D11: =8203000000 -> 8203000000 | E11: 652002048 | F11: 8233687005 | G11: 56611569049 | H11: 65248902 | I11: 5168269890 | J11: 88570555 | K11: =3149722956 -> 3149722956 | L11: 1661948724 | M11: =2257992725 -> 2257992725 | N11: =SUM(B11:H11)/SUM(B11:M11) -> 0.85730677 | O11: =SUM(I11:M11) -> 12326504850 | R11: 10bps redepemption | S11: 90 | T11: 450 | U11: 150 | V11: 90 | W11: 27983 | X11: =L11/W11 -> 59391.371 | Y11: =L11/(L11+M11) -> 0.42397284
A12: 45291 | B12: - | C12: 394746540 | D12: =9359124175 -> 9359124175 | E12: 815301051 | F12: 8339339590 | G12: 63086013400 | H12: 69259151 | I12: 4804666695 | J12: 44412069 | K12: =3514935634 -> 3514935634 | L12: 2820162484 | M12: =3772433767 -> 3772433767 | N12: =SUM(B12:H12)/SUM(B12:M12) -> 0.84584055 | O12: =SUM(I12:M12) -> 14956610649 | R12: 10bps redepemption | S12: 83 | T12: 423 | U12: 137 | V12: 90 | W12: 44167 | X12: =L12/W12 -> 63852.254 | Y12: =L12/(L12+M12) -> 0.42777722
A13: 45382 | B13: - | C13: 100264024 | D13: =11311946813 -> 11311946813 | E13: 838514084 | F13: 6279586483 | G13: 74045290303 | H13: 122452086 | I13: 4735309369 | J13: 25111317 | K13: =3650599989 -> 3650599989 | L13: 5374726904 | M13: =3805605037 -> 3805605037 | N13: =SUM(B13:H13)/SUM(B13:M13) -> 0.84049826 | O13: =SUM(I13:M13) -> 17591352616 | R13: 10bps redepemption | S13: 90 | T13: 250 | U13: 150 | V13: 90 | W13: 71326 | X13: =L13/W13 -> 75354.386 | Y13: =L13/(L13+M13) -> 0.58546106
A14: 45473 | B14: - | C14: 109867228 | D14: =11286972273 -> 11286972273 | E14: 997373133 | F14: 6355402510 | G14: 80948647984 | H14: 72412344 | I14: 6571282257 | J14: 17377107 | K14: =3814334566 -> 3814334566 | L14: 4734040881 | M14: =3528626010 -> 3528626010 | N14: =SUM(B14:H14)/SUM(B14:M14) -> 0.8423992 | O14: =SUM(I14:M14) -> 18665660821 | R14: 10bps redepemption | S14: 90 | T14: 360 | U14: 180 | V14: 90 | W14: 62824 | X14: =L14/W14 -> 75354.019 | Y14: =L14/(L14+M14) -> 0.57294345
A15: 45565 | B15: - | C15: 78413266 | D15: =12542965206 -> 12542965206 | E15: 1566204143 | F15: =6436961021 -> 6436961021 | G15: 84548020412 | H15: 91310586 | I15: 6721817210 | J15: 17547614 | K15: =4962116508 -> 4962116508 | L15: 4782917086 | M15: =3723727227 -> 3723727227 | N15: =SUM(B15:H15)/SUM(B15:M15) -> 0.83894315 | O15: =SUM(I15:M15) -> 20208125645 | R15: 10bps redepemption | S15: 90 | T15: 270 | U15: 180 | V15: 90 | W15: 63473 | X15: =L15/W15 -> 75353.569 | Y15: =L15/(L15+M15) -> 0.56225662
A16: 45657 | B16: - | C16: 108844601 | D16: =14101623321 -> 14101623321 | E16: 3077452467 | F16: 6506444067 | G16: 94471651607 | H16: 69263354 | I16: 8194007406 | J16: 14270773 | K16: =5318875241 -> 5318875241 | L16: 7857529277 | M16: =3984793433 -> 3984793433 | N16: =SUM(B16:H16)/SUM(B16:M16) -> 0.82346112 | O16: =SUM(I16:M16) -> 25369476130 | R16: 10bps redepemption | S16: 90 | T16: 300 | U16: 150 | V16: 90 | W16: 93812 | X16: =L16/W16 -> 83758.253 | Y16: =L16/(L16+M16) -> 0.66351251
A17: 45747 | B17: - | C17: 64302555 | D17: =15093981718 -> 15093981718 | E17: 1613610695 | F17: 6285638008 | G17: 98523657338 | H17: 65886184 | I17: 8825524405 | J17: 14354777 | K17: =6663205657 -> 6663205657 | L17: 7662210442 | M17: =4462144209 -> 4462144209 | N17: =SUM(B17:H17)/SUM(B17:M17) -> 0.81492193 | O17: =SUM(I17:M17) -> 27627439490 | R17: 10bps redepemption | S17: 90 | T17: 270 | U17: 120 | V17: 90 | W17: 82704 | X17: =L17/W17 -> 92646.189 | Y17: =L17/(L17+M17) -> 0.63196852
A18: 45838 | B18: - | C18: 32430726 | D18: =16341965339 -> 16341965339 | E18: 1666870344 | F18: 6345999587 | G18: 105518993610 | H18: 48169774 | I18: 10137145089 | J18: 14605090 | K18: =8725417224 -> 8725417224 | L18: 8928174931 | M18: =4815162084 -> 4815162084 | N18: =SUM(B18:H18)/SUM(B18:M18) -> 0.79935096 | O18: =SUM(I18:M18) -> 32620504418 | R18: 10bps redepemption | S18: 90 | T18: 360 | U18: 120 | V18: 90 | W18: 107240 | X18: =L18/W18 -> 83254.149 | Y18: =L18/(L18+M18) -> 0.64963661
A19: 45930 | B19: - | C19: 30100334 | D19: =17991468781 -> 17991468781 | E19: 3056191686 | F19: 6409774689 | G19: 112417034272 | H19: 47901280 | I19: 14604086904 | J19: 14672361 | K19: =12921449635 -> 12921449635 | L19: 9856011011 | M19: =3874458261 -> 3874458261 | N19: =SUM(B19:H19)/SUM(B19:M19) -> 0.77226597 | O19: =SUM(I19:M19) -> 41270678172 | R19: 10bps redepemption | S19: 90 | T19: 270 | U19: 90 | V19: 90 | W19: 114160 | X19: =L19/W19 -> 86335.065 | Y19: =L19/(L19+M19) -> 0.7178204
A20: 46022 | B20: - | C20: 33952735 | D20: =19279408559 -> 19279408559 | E20: 5548439332 | F20: 0 | G20: 122325714946 | H20: 0 | I20: 17043516665 | J20: 3031239 | K20: =17450435088 -> 17450435088 | L20: 8430374292 | M20: =2762856288 -> 2762856288 | N20: =SUM(B20:H20)/SUM(B20:M20) -> 0.76311307 | O20: =SUM(I20:M20) -> 45690213572 | R20: 10bps redepemption | S20: 90 | T20: - | U20: 360 | V20: 90 | W20: 87647 | X20: =L20/W20 -> 96185.543 | Y20: =L20/(L20+M20) -> 0.75316721
R21: =SUM(B21:M21)-ReservesUSDT!B21 -> 0
R22: =SUM(B22:M22)-ReservesUSDT!B22 -> 0
R23: =SUM(B23:M23)-ReservesUSDT!B23 -> 0
R24: =SUM(B24:M24)-ReservesUSDT!B24 -> 0
R25: =SUM(B25:M25)-ReservesUSDT!B25 -> 0
R26: =SUM(B26:M26)-ReservesUSDT!B26 -> 0
R27: =SUM(B27:M27)-ReservesUSDT!B27 -> 0
R28: =SUM(B28:M28)-ReservesUSDT!B28 -> 0
R29: =SUM(B29:M29)-ReservesUSDT!B29 -> 0
R30: =SUM(B30:M30)-ReservesUSDT!B30 -> 0

Sheet Tether Assets
I1: Duration o/n repo: | J1: =1/360 -> 0.0027777778 | L1: Duration MM | M1: =2/360 -> 0.0055555556
A2: Date | B2: CDs | C2: # BTC | D2: BTC Price | E2: BTC Value | F2: Oz Gold | G2: Gold Price | H2: Gold Value | I2: Cash + Banks Depo | J2: O/n Repo MtM | K2: Reverse Repo MtM | L2: Reverse Repo Duration | M2: Money Makts MtM | N2: Tbills Notional | O2: Tbills Duration | P2: Non US Tbills Notionals | Q2: NonUSTBills Duration | R2: Secured Loans | S2: Corporate Bonds | T2: Corporate Bonds | U2: Other inv | V2: Total Asset Values | W2: L | X2: D | Y2: K | Z2: New Estimate Reserves | AA2: USDT Market Cap
A3: 44834 | B3: 49981855 | C3: 81315.278 | D3: =_xlfn.XLOOKUP(A3,'BBG Data'!A:A,'BBG Data'!B:B) -> 19425.13 | E3: =C3*D3 -> 1.5795598e+09 | F3: 1827431.7 | G3: =_xlfn.XLOOKUP(A3,'BBG Data'!A:A,'BBG Data'!C:C) -> 1660.61 | H3: =G3*F3 -> 3.0346514e+09 | I3: 6077722223 | J3: 2.721433e+09 | K3: 3.0238144e+08 | L3: 90 | M3: 7101935591 | N3: 39678465980 | O3: 45 | P3: 182114357 | Q3: 90 | R3: 6135946415 | S3: 1.5971849e+08 | T3: 180 | U3: 1046907100 | V3: =U3+S3+R3+P3+N3+M3+K3+J3+I3+H3+E3+B3 -> 6.8070818e+10 | W3: =(I3+J3)/V3 -> 0.12926472 | X3: =N3/V3 -> 0.5828998 | Y3: =USDT_FinalReserves!G2/USDT_FinalReserves!$F2 -> 0.0037687243 | Z3: 6.8276251e+10 | AA3: 6.8018937e+10
A4: 44835 | B4: 49981855 | C4: 81315.278 | D4: =_xlfn.XLOOKUP(A4,'BBG Data'!A:A,'BBG Data'!B:B) -> 19252.71 | E4: =C4*D4 -> 1.5655395e+09 | F4: 1827431.7 | G4: =_xlfn.XLOOKUP(A4,'BBG Data'!A:A,'BBG Data'!C:C) -> 1660.61 | H4: =G4*F4 -> 3.0346514e+09 | I4: 6077722223 | J4: =J3-$J$1*J3*_xlfn.XLOOKUP(A4,'BBG Data'!A:A,'BBG Data'!F:F) -> 2.721433e+09 | K4: =K3-K3*L4/360*_xlfn.XLOOKUP(A4,'BBG Data'!A:A,'BBG Data'!J:J) -> 3.0238144e+08 | L4: 90 | M4: =M3-M3*$M$1*_xlfn.XLOOKUP(A4,'BBG Data'!A:A,'BBG Data'!F:F) -> 7101935591 | N4: =N3-N3*O4/360*_xlfn.XLOOKUP('Tether Assets'!A4,'BBG Data'!A:A,'BBG Data'!V:V) -> 39678465980 | O4: 45 | P4: =P3-P3*Q4/360*_xlfn.XLOOKUP(A4,'BBG Data'!A:A,'BBG Data'!V:V) -> 182114357 | Q4: 90 | R4: 6135946415 | S4: =S3-S3*T4/360*_xlfn.XLOOKUP('Tether Assets'!A4,'BBG Data'!A:A,'BBG Data'!AB:AB) -> 1.5971849e+08 | T4: 180 | U4: 1046907100 | V4: =U4+S4+R4+P4+N4+M4+K4+J4+I4+H4+E4+B4 -> 6.8056797e+10 | W4: =(I4+J4)/V4 -> 0.12929135 | X4: =N4/V4 -> 0.58301988 | Y4: =USDT_FinalReserves!G3/USDT_FinalReserves!$F3 -> 0.0035634907 | Z4: 6.8275764e+10 | AA4: 6.8032464e+10
A5: 44836 | B5: 49981855 | C5: 81315.278 | D5: =_xlfn.XLOOKUP(A5,'BBG Data'!A:A,'BBG Data'!B:B) -> 19234.63 | E5: =C5*D5 -> 1.5640693e+09 | F5: 1827431.7 | G5: =_xlfn.XLOOKUP(A5,'BBG Data'!A:A,'BBG Data'!C:C) -> 1660.61 | H5: =G5*F5 -> 3.0346514e+09 | I5: 6077722223 | J5: =J4-$J$1*J4*_xlfn.XLOOKUP(A5,'BBG Data'!A:A,'BBG Data'!F:F) -> 2.721433e+09 | K5: =K4-K4*L5/360*_xlfn.XLOOKUP(A5,'BBG Data'!A:A,'BBG Data'!J:J) -> 3.0238144e+08 | L5: 90 | M5: =M4-M4*$M$1*_xlfn.XLOOKUP(A5,'BBG Data'!A:A,'BBG Data'!F:F) -> 7101935591 | N5: =N4-N4*O5/360*_xlfn.XLOOKUP('Tether Assets'!A5,'BBG Data'!A:A,'BBG Data'!V:V) -> 39678465980 | O5: 45 | P5: =P4-P4*Q5/360*_xlfn.XLOOKUP(A5,'BBG Data'!A:A,'BBG Data'!V:V) -> 182114357 | Q5: 90 | R5: 6135946415 | S5: =S4-S4*T5/360*_xlfn.XLOOKUP('Tether Assets'!A5,'BBG Data'!A:A,'BBG Data'!AB:AB) -> 1.5971849e+08 | T5: 180 | U5: 1046907100 | V5: =U5+S5+R5+P5+N5+M5+K5+J5+I5+H5+E5+B5 -> 6.8055327e+10 | W5: =(I5+J5)/V5 -> 0.12929414 | X5: =N5/V5 -> 0.58303248 | Y5: =USDT_FinalReserves!G4/USDT_FinalReserves!$F4 -> 0.003747203 | Z5: 6.8240924e+10 | AA5: 6.7985211e+10
A6: 44837 | B6: 49981855 | C6: 81315.278 | D6: =_xlfn.XLOOKUP(A6,'BBG Data'!A:A,'BBG Data'!B:B) -> 19597.13 | E6: =C6*D6 -> 1.5935461e+09 | F6: 1827431.7 | G6: =_xlfn.XLOOKUP(A6,'BBG Data'!A:A,'BBG Data'!C:C) -> 1699.89 | H6: =G6*F6 -> 3.1064329e+09 | I6: 6077722223 | J6: =J5-$J$1*J5*_xlfn.XLOOKUP(A6,'BBG Data'!A:A,'BBG Data'!F:F) -> 2.7212818e+09 | K6: =K5-K5*L6/360*_xlfn.XLOOKUP(A6,'BBG Data'!A:A,'BBG Data'!J:J) -> 3.0207377e+08 | L6: 90 | M6: =M5-M5*$M$1*_xlfn.XLOOKUP(A6,'BBG Data'!A:A,'BBG Data'!F:F) -> 7.1011465e+09 | N6: =N5-N5*O6/360*_xlfn.XLOOKUP('Tether Assets'!A6,'BBG Data'!A:A,'BBG Data'!V:V) -> 3.9876858e+10 | O6: 45 | P6: =P5-P5*Q6/360*_xlfn.XLOOKUP(A6,'BBG Data'!A:A,'BBG Data'!V:V) -> 1.839355e+08 | Q6: 90 | R6: 6135946415 | S6: =S5-S5*T6/360*_xlfn.XLOOKUP('Tether Assets'!A6,'BBG Data'!A:A,'BBG Data'!AB:AB) -> 1.6444616e+08 | T6: 180 | U6: 1046907100 | V6: =U6+S6+R6+P6+N6+M6+K6+J6+I6+H6+E6+B6 -> 6.8360279e+10 | W6: =(I6+J6)/V6 -> 0.12871516 | X6: =N6/V6 -> 0.58333376 | Y6: =USDT_FinalReserves!G5/USDT_FinalReserves!$F5 -> 0.0082128578 | Z6: 6.8414751e+10 | AA6: 6.7852871e+10
A7: 44838 | B7: 49981855 | C7: 81315.278 | D7: =_xlfn.XLOOKUP(A7,'BBG Data'!A:A,'BBG Data'!B:B) -> 20340.91 | E7: =C7*D7 -> 1.6540268e+09 | F7: 1827431.7 | G7: =_xlfn.XLOOKUP(A7,'BBG Data'!A:A,'BBG Data'!C:C) -> 1726.13 | H7: =G7*F7 -> 3.1543847e+09 | I7: 6077722223 | J7: =J6-$J$1*J6*_xlfn.XLOOKUP(A7,'BBG Data'!A:A,'BBG Data'!F:F) -> 2.7209794e+09 | K7: =K6-K6*L7/360*_xlfn.XLOOKUP(A7,'BBG Data'!A:A,'BBG Data'!J:J) -> 3.009425e+08 | L7: 90 | M7: =M6-M6*$M$1*_xlfn.XLOOKUP(A7,'BBG Data'!A:A,'BBG Data'!F:F) -> 7.0995685e+09 | N7: =N6-N6*O7/360*_xlfn.XLOOKUP('Tether Assets'!A7,'BBG Data'!A:A,'BBG Data'!V:V) -> 3.9114213e+10 | O7: 45 | P7: =P6-P6*Q7/360*_xlfn.XLOOKUP(A7,'BBG Data'!A:A,'BBG Data'!V:V) -> 1.7689997e+08 | Q7: 90 | R7: 6135946415 | S7: =S6-S6*T7/360*_xlfn.XLOOKUP('Tether Assets'!A7,'BBG Data'!A:A,'BBG Data'!AB:AB) -> 1.681462e+08 | T7: 180 | U7: 1046907100 | V7: =U7+S7+R7+P7+N7+M7+K7+J7+I7+H7+E7+B7 -> 6.7699719e+10 | W7: =(I7+J7)/V7 -> 0.12996659 | X7: =N7/V7 -> 0.57776035 | Y7: =USDT_FinalReserves!G6/USDT_FinalReserves!$F6 -> -0.0059517018 | Z7: 6.755343e+10 | AA7: 6.7955488e+10
A8: 44839 | B8: 49981855 | C8: 81315.278 | D8: =_xlfn.XLOOKUP(A8,'BBG Data'!A:A,'BBG Data'!B:B) -> 19988.42 | E8: =C8*D8 -> 1.6253639e+09 | F8: 1827431.7 | G8: =_xlfn.XLOOKUP(A8,'BBG Data'!A:A,'BBG Data'!C:C) -> 1716.26 | H8: =G8*F8 -> 3.136348e+09 | I8: 6077722223 | J8: =J7-$J$1*J7*_xlfn.XLOOKUP(A8,'BBG Data'!A:A,'BBG Data'!F:F) -> 2.7209794e+09 | K8: =K7-K7*L8/360*_xlfn.XLOOKUP(A8,'BBG Data'!A:A,'BBG Data'!J:J) -> 2.9694448e+08 | L8: 90 | M8: =M7-M7*$M$1*_xlfn.XLOOKUP(A8,'BBG Data'!A:A,'BBG Data'!F:F) -> 7.0995685e+09 | N8: =N7-N7*O8/360*_xlfn.XLOOKUP('Tether Assets'!A8,'BBG Data'!A:A,'BBG Data'!V:V) -> 3.9163106e+10 | O8: 45 | P8: =P7-P7*Q8/360*_xlfn.XLOOKUP(A8,'BBG Data'!A:A,'BBG Data'!V:V) -> 1.7734222e+08 | Q8: 90 | R8: 6135946415 | S8: =S7-S7*T8/360*_xlfn.XLOOKUP('Tether Assets'!A8,'BBG Data'!A:A,'BBG Data'!AB:AB) -> 1.6775106e+08 | T8: 180 | U8: 1046907100 | V8: =U8+S8+R8+P8+N8+M8+K8+J8+I8+H8+E8+B8 -> 6.7697961e+10 | W8: =(I8+J8)/V8 -> 0.12996996 | X8: =N8/V8 -> 0.57849757 | Y8: =USDT_FinalReserves!G7/USDT_FinalReserves!$F7 -> 0.003742858 | Z8: 6.8402494e+10 | AA8: 6.8146473e+10
A9: 44840 | B9: 49981855 | C9: 81315.278 | D9: =_xlfn.XLOOKUP(A9,'BBG Data'!A:A,'BBG Data'!B:B) -> 20051.13 | E9: =C9*D9 -> 1.6304632e+09 | F9: 1827431.7 | G9: =_xlfn.XLOOKUP(A9,'BBG Data'!A:A,'BBG Data'!C:C) -> 1712.53 | H9: =G9*F9 -> 3.1295317e+09 | I9: 6077722223 | J9: =J8-$J$1*J8*_xlfn.XLOOKUP(A9,'BBG Data'!A:A,'BBG Data'!F:F) -> 2.7209038e+09 | K9: =K8-K8*L9/360*_xlfn.XLOOKUP(A9,'BBG Data'!A:A,'BBG Data'!J:J) -> 2.9275533e+08 | L9: 90 | M9: =M8-M8*$M$1*_xlfn.XLOOKUP(A9,'BBG Data'!A:A,'BBG Data'!F:F) -> 7.099174e+09 | N9: =N8-N8*O9/360*_xlfn.XLOOKUP('Tether Assets'!A9,'BBG Data'!A:A,'BBG Data'!V:V) -> 3.9138629e+10 | O9: 45 | P9: =P8-P8*Q9/360*_xlfn.XLOOKUP(A9,'BBG Data'!A:A,'BBG Data'!V:V) -> 1.7712054e+08 | Q9: 90 | R9: 6135946415 | S9: =S8-S8*T9/360*_xlfn.XLOOKUP('Tether Assets'!A9,'BBG Data'!A:A,'BBG Data'!AB:AB) -> 1.652264e+08 | T9: 180 | U9: 1046907100 | V9: =U9+S9+R9+P9+N9+M9+K9+J9+I9+H9+E9+B9 -> 6.7664362e+10 | W9: =(I9+J9)/V9 -> 0.13003339 | X9: =N9/V9 -> 0.57842309 | Y9: =USDT_FinalReserves!G8/USDT_FinalReserves!$F8 -> 0.0032740351 | Z9: 6.8473697e+10 | AA9: 6.8249512e+10
A10: 44841 | B10: 49981855 | C10: 81315.278 | D10: =_xlfn.XLOOKUP(A10,'BBG Data'!A:A,'BBG Data'!B:B) -> 19551.56 | E10: =C10*D10 -> 1.5898405e+09 | F10: 1827431.7 | G10: =_xlfn.XLOOKUP(A10,'BBG Data'!A:A,'BBG Data'!C:C) -> 1694.82 | H10: =G10*F10 -> 3.0971678e+09 | I10: 6077722223 | J10: =J9-$J$1*J9*_xlfn.XLOOKUP(A10,'BBG Data'!A:A,'BBG Data'!F:F) -> 2.7209038e+09 | K10: =K9-K9*L10/360*_xlfn.XLOOKUP(A10,'BBG Data'!A:A,'BBG Data'!J:J) -> 2.915082e+08 | L10: 90 | M10: =M9-M9*$M$1*_xlfn.XLOOKUP(A10,'BBG Data'!A:A,'BBG Data'!F:F) -> 7.099174e+09 | N10: =N9-N9*O10/360*_xlfn.XLOOKUP('Tether Assets'!A10,'BBG Data'!A:A,'BBG Data'!V:V) -> 3.924626e+10 | O10: 45 | P10: =P9-P9*Q10/360*_xlfn.XLOOKUP(A10,'BBG Data'!A:A,'BBG Data'!V:V) -> 1.780947e+08 | Q10: 90 | R10: 6135946415 | S10: =S9-S9*T10/360*_xlfn.XLOOKUP('Tether Assets'!A10,'BBG Data'!A:A,'BBG Data'!AB:AB) -> 1.5603982e+08 | T10: 180 | U10: 1046907100 | V10: =U10+S10+R10+P10+N10+M10+K10+J10+I10+H10+E10+B10 -> 6.7689547e+10 | W10: =(I10+J10)/V10 -> 0.129985 | X10: =N10/V10 -> 0.57979795 | Y10: =USDT_FinalReserves!G9/USDT_FinalReserves!$F9 -> 0.004139391 | Z10: 6.8523834e+10 | AA10: 6.8240187e+10
A11: 44842 | B11: 49981855 | C11: 81315.278 | D11: =_xlfn.XLOOKUP(A11,'BBG Data'!A:A,'BBG Data'!B:B) -> 19456.38 | E11: =C11*D11 -> 1.5821009e+09 | F11: 1827431.7 | G11: =_xlfn.XLOOKUP(A11,'BBG Data'!A:A,'BBG Data'!C:C) -> 1694.82 | H11: =G11*F11 -> 3.0971678e+09 | I11: 6077722223 | J11: =J10-$J$1*J10*_xlfn.XLOOKUP(A11,'BBG Data'!A:A,'BBG Data'!F:F) -> 2.7209038e+09 | K11: =K10-K10*L11/360*_xlfn.XLOOKUP(A11,'BBG Data'!A:A,'BBG Data'!J:J) -> 2.915082e+08 | L11: 90 | M11: =M10-M10*$M$1*_xlfn.XLOOKUP(A11,'BBG Data'!A:A,'BBG Data'!F:F) -> 7.099174e+09 | N11: =N10-N10*O11/360*_xlfn.XLOOKUP('Tether Assets'!A11,'BBG Data'!A:A,'BBG Data'!V:V) -> 3.924626e+10 | O11: 45 | P11: =P10-P10*Q11/360*_xlfn.XLOOKUP(A11,'BBG Data'!A:A,'BBG Data'!V:V) -> 1.780947e+08 | Q11: 90 | R11: 6135946415 | S11: =S10-S10*T11/360*_xlfn.XLOOKUP('Tether Assets'!A11,'BBG Data'!A:A,'BBG Data'!AB:AB) -> 1.5603982e+08 | T11: 180 | U11: 1046907100 | V11: =U11+S11+R11+P11+N11+M11+K11+J11+I11+H11+E11+B11 -> 6.7681807e+10 | W11: =(I11+J11)/V11 -> 0.12999987 | X11: =N11/V11 -> 0.57986425 | Y11: =USDT_FinalReserves!G10/USDT_FinalReserves!$F10 -> 0.0036548027 | Z11: 6.8610782e+10 | AA11: 6.8360023e+10
A12: 44843 | B12: 49981855 | C12: 81315.278 | D12: =_xlfn.XLOOKUP(A12,'BBG Data'!A:A,'BBG Data'!B:B) -> 19485.5 | E12: =C12*D12 -> 1.5844689e+09 | F12: 1827431.7 | G12: =_xlfn.XLOOKUP(A12,'BBG Data'!A:A,'BBG Data'!C:C) -> 1694.82 | H12: =G12*F12 -> 3.0971678e+09 | I12: 6077722223 | J12: =J11-$J$1*J11*_xlfn.XLOOKUP(A12,'BBG Data'!A:A,'BBG Data'!F:F) -> 2.7209038e+09 | K12: =K11-K11*L12/360*_xlfn.XLOOKUP(A12,'BBG Data'!A:A,'BBG Data'!J:J) -> 2.915082e+08 | L12: 90 | M12: =M11-M11*$M$1*_xlfn.XLOOKUP(A12,'BBG Data'!A:A,'BBG Data'!F:F) -> 7.099174e+09 | N12: =N11-N11*O12/360*_xlfn.XLOOKUP('Tether Assets'!A12,'BBG Data'!A:A,'BBG Data'!V:V) -> 3.924626e+10 | O12: 45 | P12: =P11-P11*Q12/360*_xlfn.XLOOKUP(A12,'BBG Data'!A:A,'BBG Data'!V:V) -> 1.780947e+08 | Q12: 90 | R12: 6135946415 | S12: =S11-S11*T12/360*_xlfn.XLOOKUP('Tether Assets'!A12,'BBG Data'!A:A,'BBG Data'!AB:AB) -> 1.5603982e+08 | T12: 180 | U12: 1046907100 | V12: =U12+S12+R12+P12+N12+M12+K12+J12+I12+H12+E12+B12 -> 6.7684175e+10 | W12: =(I12+J12)/V12 -> 0.12999532 | X12: =N12/V12 -> 0.57984396 | Y12: =USDT_FinalReserves!G11/USDT_FinalReserves!$F11 -> 0.003803577 | Z12: 6.8645759e+10 | AA12: 6.838466e+10
A13: 44844 | B13: 49981855 | C13: 81315.278 | D13: =_xlfn.XLOOKUP(A13,'BBG Data'!A:A,'BBG Data'!B:B) -> 19241.2 | E13: =C13*D13 -> 1.5646035e+09 | F13: 1827431.7 | G13: =_xlfn.XLOOKUP(A13,'BBG Data'!A:A,'BBG Data'!C:C) -> 1668.61 | H13: =G13*F13 -> 3.0492709e+09 | I13: 6077722223 | J13: =J12-$J$1*J12*_xlfn.XLOOKUP(A13,'BBG Data'!A:A,'BBG Data'!F:F) -> 2.7209038e+09 | K13: =K12-K12*L13/360*_xlfn.XLOOKUP(A13,'BBG Data'!A:A,'BBG Data'!J:J) -> 2.915082e+08 | L13: 90 | M13: =M12-M12*$M$1*_xlfn.XLOOKUP(A13,'BBG Data'!A:A,'BBG Data'!F:F) -> 7.099174e+09 | N13: =N12-N12*O13/360*_xlfn.XLOOKUP('Tether Assets'!A13,'BBG Data'!A:A,'BBG Data'!V:V) -> 3.924626e+10 | O13: 45 | P13: =P12-P12*Q13/360*_xlfn.XLOOKUP(A13,'BBG Data'!A:A,'BBG Data'!V:V) -> 1.780947e+08 | Q13: 90 | R13: 6135946415 | S13: =S12-S12*T13/360*_xlfn.XLOOKUP('Tether Assets'!A13,'BBG Data'!A:A,'BBG Data'!AB:AB) -> 1.5603982e+08 | T13: 180 | U13: 1046907100 | V13: =U13+S13+R13+P13+N13+M13+K13+J13+I13+H13+E13+B13 -> 6.7616413e+10 | W13: =(I13+J13)/V13 -> 0.1301256 | X13: =N13/V13 -> 0.58042506 | Y13: =USDT_FinalReserves!G12/USDT_FinalReserves!$F12 -> 0.0027703435 | Z13: 6.8498065e+10 | AA13: 6.8308302e+10
A14: 44845 | B14: 49981855 | C14: 81315.278 | D14: =_xlfn.XLOOKUP(A14,'BBG Data'!A:A,'BBG Data'!B:B) -> 19019.1 | E14: =C14*D14 -> 1.5465434e+09 | F14: 1827431.7 | G14: =_xlfn.XLOOKUP(A14,'BBG Data'!A:A,'BBG Data'!C:C) -> 1666.34 | H14: =G14*F14 -> 3.0451226e+09 | I14: 6077722223 | J14: =J13-$J$1*J13*_xlfn.XLOOKUP(A14,'BBG Data'!A:A,'BBG Data'!F:F) -> 2.7209038e+09 | K14: =K13-K13*L14/360*_xlfn.XLOOKUP(A14,'BBG Data'!A:A,'BBG Data'!J:J) -> 2.882076e+08 | L14: 90 | M14: =M13-M13*$M$1*_xlfn.XLOOKUP(A14,'BBG Data'!A:A,'BBG Data'!F:F) -> 7.099174e+09 | N14: =N13-N13*O14/360*_xlfn.XLOOKUP('Tether Assets'!A14,'BBG Data'!A:A,'BBG Data'!V:V) -> 3.8834175e+10 | O14: 45 | P14: =P13-P13*Q14/360*_xlfn.XLOOKUP(A14,'BBG Data'!A:A,'BBG Data'!V:V) -> 1.7435471e+08 | Q14: 90 | R14: 6135946415 | S14: =S13-S13*T14/360*_xlfn.XLOOKUP('Tether Assets'!A14,'BBG Data'!A:A,'BBG Data'!AB:AB) -> 1.5231827e+08 | T14: 180 | U14: 1046907100 | V14: =U14+S14+R14+P14+N14+M14+K14+J14+I14+H14+E14+B14 -> 6.7171357e+10 | W14: =(I14+J14)/V14 -> 0.13098777 | X14: =N14/V14 -> 0.57813593 | Y14: =USDT_FinalReserves!G13/USDT_FinalReserves!$F13 -> -0.0028319906 | Z14: 6.8272184e+10 | AA14: 6.846553e+10
A15: 44846 | B15: 49981855 | C15: 81315.278 | D15: =_xlfn.XLOOKUP(A15,'BBG Data'!A:A,'BBG Data'!B:B) -> 19169.43 | E15: =C15*D15 -> 1.5587675e+09 | F15: 1827431.7 | G15: =_xlfn.XLOOKUP(A15,'BBG Data'!A:A,'BBG Data'!C:C) -> 1673.19 | H15: =G15*F15 -> 3.0576405e+09 | I15: 6077722223 | J15: =J14-$J$1*J14*_xlfn.XLOOKUP(A15,'BBG Data'!A:A,'BBG Data'!F:F) -> 2.7209794e+09 | K15: =K14-K14*L15/360*_xlfn.XLOOKUP(A15,'BBG Data'!A:A,'BBG Data'!J:J) -> 2.8511945e+08 | L15: 90 | M15: =M14-M14*$M$1*_xlfn.XLOOKUP(A15,'BBG Data'!A:A,'BBG Data'!F:F) -> 7.0995684e+09 | N15: =N14-N14*O15/360*_xlfn.XLOOKUP('Tether Assets'!A15,'BBG Data'!A:A,'BBG Data'!V:V) -> 3.7979823e+10 | O15: 45 | P15: =P14-P14*Q15/360*_xlfn.XLOOKUP(A15,'BBG Data'!A:A,'BBG Data'!V:V) -> 1.6668311e+08 | Q15: 90 | R15: 6135946415 | S15: =S14-S14*T15/360*_xlfn.XLOOKUP('Tether Assets'!A15,'BBG Data'!A:A,'BBG Data'!AB:AB) -> 1.5045237e+08 | T15: 180 | U15: 1046907100 | V15: =U15+S15+R15+P15+N15+M15+K15+J15+I15+H15+E15+B15 -> 6.6329591e+10 | W15: =(I15+J15)/V15 -> 0.13265123 | X15: =N15/V15 -> 0.57259245 | Y15: =USDT_FinalReserves!G14/USDT_FinalReserves!$F14 -> -0.0088740959 | Z15: 6.7826661e+10 | AA15: 6.8428562e+10
... A94: 44925 | B94: 49981855 | C94: 81315.278 | D94: =_xlfn.XLOOKUP(A94,'BBG Data'!A:A,'BBG Data'!B:B) -> 16579.06 | E94: =C94*D94 -> 1.3481309e+09 | F94: 1827431.7 | G94: =_xlfn.XLOOKUP(A94,'BBG Data'!A:A,'BBG Data'!C:C) -> 1824.02 | H94: =G94*F94 -> 3.333272e+09 | I94: 6077722223 | J94: =J93-$J$1*J93*_xlfn.XLOOKUP(A94,'BBG Data'!A:A,'BBG Data'!F:F) -> 2.7114639e+09 | K94: =K93-K93*L94/360*_xlfn.XLOOKUP(A94,'BBG Data'!A:A,'BBG Data'!J:J) -> 2.355567e+08 | L94: 90 | M94: =M93-M93*$M$1*_xlfn.XLOOKUP(A94,'BBG Data'!A:A,'BBG Data'!F:F) -> 7.0499539e+09 | N94: =N93-N93*O94/360*_xlfn.XLOOKUP('Tether Assets'!A94,'BBG Data'!A:A,'BBG Data'!V:V) -> 3.4517952e+10 | O94: 45 | P94: =P93-P93*Q94/360*_xlfn.XLOOKUP(A94,'BBG Data'!A:A,'BBG Data'!V:V) -> 1.3745099e+08 | Q94: 90 | R94: 6135946415 | S94: =S93-S93*T94/360*_xlfn.XLOOKUP('Tether Assets'!A94,'BBG Data'!A:A,'BBG Data'!AB:AB) -> 1.1765813e+08 | T94: 180 | U94: 1046907100 | V94: =U94+S94+R94+P94+N94+M94+K94+J94+I94+H94+E94+B94 -> 6.2761996e+10 | W94: =(I94+J94)/V94 -> 0.14003994 | X94: =N94/V94 -> 0.54998174 | Y94: =USDT_FinalReserves!G93/USDT_FinalReserves!$F93 -> 0.0050474825 | Z94: 6.6591937e+10 | AA94: 6.6255816e+10
A95: 44926 | B95: 0 | C95: 96930.631 | D95: =_xlfn.XLOOKUP(A95,'BBG Data'!A:A,'BBG Data'!B:B) -> 16539.5 | E95: =C95*D95 -> 1.6031842e+09 | F95: 1793781.2 | G95: =_xlfn.XLOOKUP(A95,'BBG Data'!A:A,'BBG Data'!C:C) -> 1824.02 | H95: =G95*F95 -> 3.2718927e+09 | I95: 5318311794 | J95: 2.7414846e+09 | K95: 3.046094e+08 | L95: 90 | M95: 7372926391 | N95: 39230259046 | O95: 60 | P95: 93849833 | Q95: 60 | R95: 5852823328 | S95: 1.7220488e+08 | T95: 180 | U95: 1074314492 | V95: =U95+S95+R95+P95+N95+M95+K95+J95+I95+H95+E95+B95 -> 6.7035861e+10 | W95: =(I95+J95)/V95 -> 0.12023112 | X95: =N95/V95 -> 0.58521303 | Y95: =USDT_FinalReserves!G94/USDT_FinalReserves!$F94 -> 0.014719972 | Z95: 6.7269245e+10 | AA95: 6.6279044e+10
A96: 44927 | B96: 0 | C96: 96930.631 | D96: =_xlfn.XLOOKUP(A96,'BBG Data'!A:A,'BBG Data'!B:B) -> 16602.63 | E96: =C96*D96 -> 1.6093034e+09 | F96: 1793781.2 | G96: =_xlfn.XLOOKUP(A96,'BBG Data'!A:A,'BBG Data'!C:C) -> 1824.02 | H96: =G96*F96 -> 3.2718927e+09 | I96: 5318311794 | J96: =J95-$J$1*J95*_xlfn.XLOOKUP(A96,'BBG Data'!A:A,'BBG Data'!F:F) -> 2.7414846e+09 | K96: =K95-K95*L96/360*_xlfn.XLOOKUP(A96,'BBG Data'!A:A,'BBG Data'!J:J) -> 3.046094e+08 | L96: 90 | M96: =M95-M95*$M$1*_xlfn.XLOOKUP(A96,'BBG Data'!A:A,'BBG Data'!F:F) -> 7372926391 | N96: =N95-N95*O96/360*_xlfn.XLOOKUP('Tether Assets'!A96,'BBG Data'!A:A,'BBG Data'!V:V) -> 39230259046 | O96: 60 | P96: =P95-P95*Q96/360*_xlfn.XLOOKUP(A96,'BBG Data'!A:A,'BBG Data'!V:V) -> 93849833 | Q96: 60 | R96: 5852823328 | S96: =S95-S95*T96/360*_xlfn.XLOOKUP('Tether Assets'!A96,'BBG Data'!A:A,'BBG Data'!AB:AB) -> 1.7220488e+08 | T96: 180 | U96: 1074314492 | V96: =U96+S96+R96+P96+N96+M96+K96+J96+I96+H96+E96+B96 -> 6.704198e+10 | W96: =(I96+J96)/V96 -> 0.12022014 | X96: =N96/V96 -> 0.58515961 | Y96: =USDT_FinalReserves!G95/USDT_FinalReserves!$F95 -> 0.014809903 | Z96: 6.7222003e+10 | AA96: 6.6226452e+10
A97: 44928 | B97: 0 | C97: 96930.631 | D97: =_xlfn.XLOOKUP(A97,'BBG Data'!A:A,'BBG Data'!B:B) -> 16750.94 | E97: =C97*D97 -> 1.6236792e+09 | F97: 1793781.2 | G97: =_xlfn.XLOOKUP(A97,'BBG Data'!A:A,'BBG Data'!C:C) -> 1824.02 | H97: =G97*F97 -> 3.2718927e+09 | I97: 5318311794 | J97: =J96-$J$1*J96*_xlfn.XLOOKUP(A97,'BBG Data'!A:A,'BBG Data'!F:F) -> 2.7414846e+09 | K97: =K96-K96*L97/360*_xlfn.XLOOKUP(A97,'BBG Data'!A:A,'BBG Data'!J:J) -> 3.046094e+08 | L97: 90 | M97: =M96-M96*$M$1*_xlfn.XLOOKUP(A97,'BBG Data'!A:A,'BBG Data'!F:F) -> 7372926391 | N97: =N96-N96*O97/360*_xlfn.XLOOKUP('Tether Assets'!A97,'BBG Data'!A:A,'BBG Data'!V:V) -> 39230259046 | O97: 60 | P97: =P96-P96*Q97/360*_xlfn.XLOOKUP(A97,'BBG Data'!A:A,'BBG Data'!V:V) -> 93849833 | Q97: 60 | R97: 5852823328 | S97: =S96-S96*T97/360*_xlfn.XLOOKUP('Tether Assets'!A97,'BBG Data'!A:A,'BBG Data'!AB:AB) -> 1.7220488e+08 | T97: 180 | U97: 1074314492 | V97: =U97+S97+R97+P97+N97+M97+K97+J97+I97+H97+E97+B97 -> 6.7056356e+10 | W97: =(I97+J97)/V97 -> 0.12019437 | X97: =N97/V97 -> 0.58503417 | Y97: =USDT_FinalReserves!G96/USDT_FinalReserves!$F96 -> 0.0149312 | Z97: 6.730683e+10 | AA97: 6.6301858e+10
A98: 44929 | B98: 0 | C98: 96930.631 | D98: =_xlfn.XLOOKUP(A98,'BBG Data'!A:A,'BBG Data'!B:B) -> 16661.86 | E98: =C98*D98 -> 1.6150446e+09 | F98: 1793781.2 | G98: =_xlfn.XLOOKUP(A98,'BBG Data'!A:A,'BBG Data'!C:C) -> 1839.48 | H98: =G98*F98 -> 3.2996246e+09 | I98: 5318311794 | J98: =J97-$J$1*J97*_xlfn.XLOOKUP(A98,'BBG Data'!A:A,'BBG Data'!F:F) -> 2.7414084e+09 | K98: =K97-K97*L98/360*_xlfn.XLOOKUP(A98,'BBG Data'!A:A,'BBG Data'!J:J) -> 3.0343741e+08 | L98: 90 | M98: =M97-M97*$M$1*_xlfn.XLOOKUP(A98,'BBG Data'!A:A,'BBG Data'!F:F) -> 7.3725168e+09 | N98: =N97-N97*O98/360*_xlfn.XLOOKUP('Tether Assets'!A98,'BBG Data'!A:A,'BBG Data'!V:V) -> 3.9269489e+10 | O98: 60 | P98: =P97-P97*Q98/360*_xlfn.XLOOKUP(A98,'BBG Data'!A:A,'BBG Data'!V:V) -> 93943683 | Q98: 60 | R98: 5852823328 | S98: =S97-S97*T98/360*_xlfn.XLOOKUP('Tether Assets'!A98,'BBG Data'!A:A,'BBG Data'!AB:AB) -> 1.7668221e+08 | T98: 180 | U98: 1074314492 | V98: =U98+S98+R98+P98+N98+M98+K98+J98+I98+H98+E98+B98 -> 6.7117597e+10 | W98: =(I98+J98)/V98 -> 0.12008356 | X98: =N98/V98 -> 0.58508486 | Y98: =USDT_FinalReserves!G97/USDT_FinalReserves!$F97 -> 0.015618984 | Z98: 6.7274003e+10 | AA98: 6.6223252e+10
A99: 44930 | B99: 0 | C99: 96930.631 | D99: =_xlfn.XLOOKUP(A99,'BBG Data'!A:A,'BBG Data'!B:B) -> 16821.82 | E99: =C99*D99 -> 1.6305496e+09 | F99: 1793781.2 | G99: =_xlfn.XLOOKUP(A99,'BBG Data'!A:A,'BBG Data'!C:C) -> 1854.56 | H99: =G99*F99 -> 3.3266748e+09 | I99: 5318311794 | J99: =J98-$J$1*J98*_xlfn.XLOOKUP(A99,'BBG Data'!A:A,'BBG Data'!F:F) -> 2.7414846e+09 | K99: =K98-K98*L99/360*_xlfn.XLOOKUP(A99,'BBG Data'!A:A,'BBG Data'!J:J) -> 3.03335e+08 | L99: 90 | M99: =M98-M98*$M$1*_xlfn.XLOOKUP(A99,'BBG Data'!A:A,'BBG Data'!F:F) -> 7.3729264e+09 | N99: =N98-N98*O99/360*_xlfn.XLOOKUP('Tether Assets'!A99,'BBG Data'!A:A,'BBG Data'!V:V) -> 3.8346656e+10 | O99: 60 | P99: =P98-P98*Q99/360*_xlfn.XLOOKUP(A99,'BBG Data'!A:A,'BBG Data'!V:V) -> 91736006 | Q99: 60 | R99: 5852823328 | S99: =S98-S98*T99/360*_xlfn.XLOOKUP('Tether Assets'!A99,'BBG Data'!A:A,'BBG Data'!AB:AB) -> 1.7647902e+08 | T99: 180 | U99: 1074314492 | V99: =U99+S99+R99+P99+N99+M99+K99+J99+I99+H99+E99+B99 -> 6.6235291e+10 | W99: =(I99+J99)/V99 -> 0.12168432 | X99: =N99/V99 -> 0.57894599 | Y99: =USDT_FinalReserves!G98/USDT_FinalReserves!$F98 -> 0.0015952806 | Z99: 6.6379954e+10 | AA99: 6.6274059e+10
A100: 44931 | B100: 0 | C100: 96930.631 | D100: =_xlfn.XLOOKUP(A100,'BBG Data'!A:A,'BBG Data'!B:B) -> 16844.62 | E100: =C100*D100 -> 1.6327596e+09 | F100: 1793781.2 | G100: =_xlfn.XLOOKUP(A100,'BBG Data'!A:A,'BBG Data'!C:C) -> 1832.89 | H100: =G100*F100 -> 3.2878036e+09 | I100: 5318311794 | J100: =J99-$J$1*J99*_xlfn.XLOOKUP(A100,'BBG Data'!A:A,'BBG Data'!F:F) -> 2.7414084e+09 | K100: =K99-K99*L100/360*_xlfn.XLOOKUP(A100,'BBG Data'!A:A,'BBG Data'!J:J) -> 3.0171974e+08 | L100: 90 | M100: =M99-M99*$M$1*_xlfn.XLOOKUP(A100,'BBG Data'!A:A,'BBG Data'!F:F) -> 7.3725168e+09 | N100: =N99-N99*O100/360*_xlfn.XLOOKUP('Tether Assets'!A100,'BBG Data'!A:A,'BBG Data'!V:V) -> 3.7694763e+10 | O100: 60 | P100: =P99-P99*Q100/360*_xlfn.XLOOKUP(A100,'BBG Data'!A:A,'BBG Data'!V:V) -> 90176494 | Q100: 60 | R100: 5852823328 | S100: =S99-S99*T100/360*_xlfn.XLOOKUP('Tether Assets'!A100,'BBG Data'!A:A,'BBG Data'!AB:AB) -> 1.7237589e+08 | T100: 180 | U100: 1074314492 | V100: =U100+S100+R100+P100+N100+M100+K100+J100+I100+H100+E100+B100 -> 6.5538973e+10 | W100: =(I100+J100)/V100 -> 0.12297599 | X100: =N100/V100 -> 0.57515035 | Y100: =USDT_FinalReserves!G99/USDT_FinalReserves!$F99 -> 0.0042518764 | Z100: 6.6528416e+10 | AA100: 6.6245546e+10
A101: 44932 | B101: 0 | C101: 96930.631 | D101: =_xlfn.XLOOKUP(A101,'BBG Data'!A:A,'BBG Data'!B:B) -> 16927.86 | E101: =C101*D101 -> 1.6408281e+09 | F101: 1793781.2 | G101: =_xlfn.XLOOKUP(A101,'BBG Data'!A:A,'BBG Data'!C:C) -> 1865.69 | H101: =G101*F101 -> 3.3466396e+09 | I101: 5318311794 | J101: =J100-$J$1*J100*_xlfn.XLOOKUP(A101,'BBG Data'!A:A,'BBG Data'!F:F) -> 2.7414084e+09 | K101: =K100-K100*L101/360*_xlfn.XLOOKUP(A101,'BBG Data'!A:A,'BBG Data'!J:J) -> 2.9945307e+08 | L101: 90 | M101: =M100-M100*$M$1*_xlfn.XLOOKUP(A101,'BBG Data'!A:A,'BBG Data'!F:F) -> 7.3725168e+09 | N101: =N100-N100*O101/360*_xlfn.XLOOKUP('Tether Assets'!A101,'BBG Data'!A:A,'BBG Data'!V:V) -> 3.7732458e+10 | O101: 60 | P101: =P100-P100*Q101/360*_xlfn.XLOOKUP(A101,'BBG Data'!A:A,'BBG Data'!V:V) -> 90266671 | Q101: 60 | R101: 5852823328 | S101: =S100-S100*T101/360*_xlfn.XLOOKUP('Tether Assets'!A101,'BBG Data'!A:A,'BBG Data'!AB:AB) -> 1.7900374e+08 | T101: 180 | U101: 1074314492 | V101: =U101+S101+R101+P101+N101+M101+K101+J101+I101+H101+E101+B101 -> 6.5648024e+10 | W101: =(I101+J101)/V101 -> 0.12277171 | X101: =N101/V101 -> 0.57476914 | Y101: =USDT_FinalReserves!G100/USDT_FinalReserves!$F100 -> 0.016356662 | Z101: 6.7380773e+10 | AA101: 6.6278649e+10
A102: 44933 | B102: 0 | C102: 96930.631 | D102: =_xlfn.XLOOKUP(A102,'BBG Data'!A:A,'BBG Data'!B:B) -> 16938.55 | E102: =C102*D102 -> 1.6418643e+09 | F102: 1793781.2 | G102: =_xlfn.XLOOKUP(A102,'BBG Data'!A:A,'BBG Data'!C:C) -> 1865.69 | H102: =G102*F102 -> 3.3466396e+09 | I102: 5318311794 | J102: =J101-$J$1*J101*_xlfn.XLOOKUP(A102,'BBG Data'!A:A,'BBG Data'!F:F) -> 2.7414084e+09 | K102: =K101-K101*L102/360*_xlfn.XLOOKUP(A102,'BBG Data'!A:A,'BBG Data'!J:J) -> 2.9945307e+08 | L102: 90 | M102: =M101-M101*$M$1*_xlfn.XLOOKUP(A102,'BBG Data'!A:A,'BBG Data'!F:F) -> 7.3725168e+09 | N102: =N101-N101*O102/360*_xlfn.XLOOKUP('Tether Assets'!A102,'BBG Data'!A:A,'BBG Data'!V:V) -> 3.7732458e+10 | O102: 60 | P102: =P101-P101*Q102/360*_xlfn.XLOOKUP(A102,'BBG Data'!A:A,'BBG Data'!V:V) -> 90266671 | Q102: 60 | R102: 5852823328 | S102: =S101-S101*T102/360*_xlfn.XLOOKUP('Tether Assets'!A102,'BBG Data'!A:A,'BBG Data'!AB:AB) -> 1.7900374e+08 | T102: 180 | U102: 1074314492 | V102: =U102+S102+R102+P102+N102+M102+K102+J102+I102+H102+E102+B102 -> 6.564906e+10 | W102: =(I102+J102)/V102 -> 0.12276977 | X102: =N102/V102 -> 0.57476006 | Y102: =USDT_FinalReserves!G101/USDT_FinalReserves!$F101 -> 0.014735524 | Z102: 6.7254363e+10 | AA102: 6.6263334e+10
A103: 44934 | B103: 0 | C103: 96930.631 | D103: =_xlfn.XLOOKUP(A103,'BBG Data'!A:A,'BBG Data'!B:B) -> 16956.66 | E103: =C103*D103 -> 1.6436198e+09 | F103: 1793781.2 | G103: =_xlfn.XLOOKUP(A103,'BBG Data'!A:A,'BBG Data'!C:C) -> 1865.69 | H103: =G103*F103 -> 3.3466396e+09 | I103: 5318311794 | J103: =J102-$J$1*J102*_xlfn.XLOOKUP(A103,'BBG Data'!A:A,'BBG Data'!F:F) -> 2.7414084e+09 | K103: =K102-K102*L103/360*_xlfn.XLOOKUP(A103,'BBG Data'!A:A,'BBG Data'!J:J) -> 2.9945307e+08 | L103: 90 | M103: =M102-M102*$M$1*_xlfn.XLOOKUP(A103,'BBG Data'!A:A,'BBG Data'!F:F) -> 7.3725168e+09 | N103: =N102-N102*O103/360*_xlfn.XLOOKUP('Tether Assets'!A103,'BBG Data'!A:A,'BBG Data'!V:V) -> 3.7732458e+10 | O103: 60 | P103: =P102-P102*Q103/360*_xlfn.XLOOKUP(A103,'BBG Data'!A:A,'BBG Data'!V:V) -> 90266671 | Q103: 60 | R103: 5852823328 | S103: =S102-S102*T103/360*_xlfn.XLOOKUP('Tether Assets'!A103,'BBG Data'!A:A,'BBG Data'!AB:AB) -> 1.7900374e+08 | T103: 180 | U103: 1074314492 | V103: =U103+S103+R103+P103+N103+M103+K103+J103+I103+H103+E103+B103 -> 6.5650816e+10 | W103: =(I103+J103)/V103 -> 0.12276649 | X103: =N103/V103 -> 0.57474469 | Y103: =USDT_FinalReserves!G102/USDT_FinalReserves!$F102 -> 0.014746317 | Z103: 6.7264353e+10 | AA103: 6.6272452e+10
A104: 44935 | B104: 0 | C104: 96930.631 | D104: =_xlfn.XLOOKUP(A104,'BBG Data'!A:A,'BBG Data'!B:B) -> 17181.34 | E104: =C104*D104 -> 1.6653981e+09 | F104: 1793781.2 | G104: =_xlfn.XLOOKUP(A104,'BBG Data'!A:A,'BBG Data'!C:C) -> 1871.81 | H104: =G104*F104 -> 3.3576175e+09 | I104: 5318311794 | J104: =J103-$J$1*J103*_xlfn.XLOOKUP(A104,'BBG Data'!A:A,'BBG Data'!F:F) -> 2.7414084e+09 | K104: =K103-K103*L104/360*_xlfn.XLOOKUP(A104,'BBG Data'!A:A,'BBG Data'!J:J) -> 3.0098852e+08 | L104: 90 | M104: =M103-M103*$M$1*_xlfn.XLOOKUP(A104,'BBG Data'!A:A,'BBG Data'!F:F) -> 7.3725168e+09 | N104: =N103-N103*O104/360*_xlfn.XLOOKUP('Tether Assets'!A104,'BBG Data'!A:A,'BBG Data'!V:V) -> 3.7707303e+10 | O104: 60 | P104: =P103-P103*Q104/360*_xlfn.XLOOKUP(A104,'BBG Data'!A:A,'BBG Data'!V:V) -> 90206493 | Q104: 60 | R104: 5852823328 | S104: =S103-S103*T104/360*_xlfn.XLOOKUP('Tether Assets'!A104,'BBG Data'!A:A,'BBG Data'!AB:AB) -> 1.8468711e+08 | T104: 180 | U104: 1074314492 | V104: =U104+S104+R104+P104+N104+M104+K104+J104+I104+H104+E104+B104 -> 6.5665575e+10 | W104: =(I104+J104)/V104 -> 0.1227389 | X104: =N104/V104 -> 0.57423243 | Y104: =USDT_FinalReserves!G103/USDT_FinalReserves!$F103 -> 0.014941439 | Z104: 6.7300933e+10 | AA104: 6.629536e+10
